Workbook

Sheet Chọn quả
A1: Quả số | B1: Khối lượng | C1: Áp suất | E1: Chọn quả | F1: Khối lượng (g) | G1: Áp suất (kG/cm2)
A2: Gốc | B2: 67.57205 | C2: 0.067572 | E2: 100C | F2: =IF(E2="",0,VLOOKUP(E2,$A$2:$C$17,2,FALSE)) -> 6757.0273 | G2: =IF(E2="",0,VLOOKUP(E2,$A$2:$C$17,3,FALSE)) -> 6.757027
A3: 1 | B3: 67.58286 | C3: 0.067583 | E3: 100A | F3: =IF(E3="",0,VLOOKUP(E3,$A$2:$C$17,2,FALSE)) -> 3378.8848 | G3: =IF(E3="",0,VLOOKUP(E3,$A$2:$C$17,3,FALSE)) -> 3.378885
A4: 2 | B4: 168.92576 | C4: 0.168926 | E4: 100B | F4: =IF(E4="",0,VLOOKUP(E4,$A$2:$C$17,2,FALSE)) -> 3378.8848 | G4: =IF(E4="",0,VLOOKUP(E4,$A$2:$C$17,3,FALSE)) -> 3.378885
A5: 4A | B5: 168.93927 | C5: 0.168939 | E5: 100D | F5: =IF(E5="",0,VLOOKUP(E5,$A$2:$C$17,2,FALSE)) -> 6757.5002 | G5: =IF(E5="",0,VLOOKUP(E5,$A$2:$C$17,3,FALSE)) -> 6.7575
A6: 4B | B6: 337.89543 | C6: 0.337895 | E6: 100E | F6: =IF(E6="",0,VLOOKUP(E6,$A$2:$C$17,2,FALSE)) -> 16893.074 | G6: =IF(E6="",0,VLOOKUP(E6,$A$2:$C$17,3,FALSE)) -> 16.893074
A7: 10 | B7: 337.90895 | C7: 0.337909 | E7: 100F | F7: =IF(E7="",0,VLOOKUP(E7,$A$2:$C$17,2,FALSE)) -> 16894.426 | G7: =IF(E7="",0,VLOOKUP(E7,$A$2:$C$17,3,FALSE)) -> 16.894426
A8: 10N | B8: 675.75708 | C8: 0.675757 | E8: 40A | F8: =IF(E8="",0,VLOOKUP(E8,$A$2:$C$17,2,FALSE)) -> 1689.341 | G8: =IF(E8="",0,VLOOKUP(E8,$A$2:$C$17,3,FALSE)) -> 1.689341
A9: 20 | B9: 675.77735 | C9: 0.675777 | E9: 40B | F9: =IF(E9="",0,VLOOKUP(E9,$A$2:$C$17,2,FALSE)) -> 1689.4424 | G9: =IF(E9="",0,VLOOKUP(E9,$A$2:$C$17,3,FALSE)) -> 1.689442
A10: 40A | B10: 1689.341 | C10: 1.689341 | E10: 20 | F10: =IF(E10="",0,VLOOKUP(E10,$A$2:$C$17,2,FALSE)) -> 675.77735 | G10: =IF(E10="",0,VLOOKUP(E10,$A$2:$C$17,3,FALSE)) -> 0.675777
A11: 40B | B11: 1689.4424 | C11: 1.689442 | F11: =IF(E11="",0,VLOOKUP(E11,$A$2:$C$17,2,FALSE)) -> 0 | G11: =IF(E11="",0,VLOOKUP(E11,$A$2:$C$17,3,FALSE)) -> 0
A12: 100A | B12: 3378.8848 | C12: 3.378885 | F12: =IF(E12="",0,VLOOKUP(E12,$A$2:$C$17,2,FALSE)) -> 0 | G12: =IF(E12="",0,VLOOKUP(E12,$A$2:$C$17,3,FALSE)) -> 0
A13: 100B | B13: 3378.8848 | C13: 3.378885 | F13: =IF(E13="",0,VLOOKUP(E13,$A$2:$C$17,2,FALSE)) -> 0 | G13: =IF(E13="",0,VLOOKUP(E13,$A$2:$C$17,3,FALSE)) -> 0
A14: 100C | B14: 6757.0273 | C14: 6.757027 | F14: =IF(E14="",0,VLOOKUP(E14,$A$2:$C$17,2,FALSE)) -> 0 | G14: =IF(E14="",0,VLOOKUP(E14,$A$2:$C$17,3,FALSE)) -> 0
A15: 100D | B15: 6757.5002 | C15: 6.7575 | F15: =IF(E15="",0,VLOOKUP(E15,$A$2:$C$17,2,FALSE)) -> 0 | G15: =IF(E15="",0,VLOOKUP(E15,$A$2:$C$17,3,FALSE)) -> 0
A16: 100E | B16: 16893.074 | C16: 16.893074 | F16: =IF(E16="",0,VLOOKUP(E16,$A$2:$C$17,2,FALSE)) -> 0 | G16: =IF(E16="",0,VLOOKUP(E16,$A$2:$C$17,3,FALSE)) -> 0
A17: 100F | B17: 16894.426 | C17: 16.894426 | F17: =IF(E17="",0,VLOOKUP(E17,$A$2:$C$17,2,FALSE)) -> 0 | G17: =IF(E17="",0,VLOOKUP(E17,$A$2:$C$17,3,FALSE)) -> 0
E18: Tổng | F18: =SUM(F2:F17) -> 58114.358 | G18: =SUM(G2:G17) -> 58.114357

Sheet KQ KĐ
A1: TRUNG TÂM ĐO LƯỜNG | E1: CỘNG HÒA XÃ HỘI CHỦ NGHĨA VIỆT NAM | J1: KẾT QUẢ KIỂM ĐỊNH (tiếp theo)
A2: PHÒNG ĐL NHIỆT-ÁP SUẤT | E2: Độc lập - Tự do - Hạnh phúc | J2: 3. Kiểm tra đo lường:
E3: Hà Nội, ngày 12 tháng 08 năm 2025 | J3: Bảng 2 - Khối lượng các quả cân
J4: TT | K4: Tên, mã số | L4: Khối lượng thực tế (g) | M4: Khối lượng danh nghĩa (g) | N4: Sai số tương đối khối lượng quả cân (%)
D5: BIÊN BẢN KIỂM ĐỊNH
E6: Số: 016/2025 | N6: Giá trị xác định | O6: Giá trị cho phép
J7: 1 | K7: 1 | L7: 33.78501 | M7: =(100*L7)/(100+N7) -> 33.783996 | N7: 0.003 | O7: 0.0375
A8: Tên trang bị ĐL-TN: | D8: Áp kế pít tông | J8: 2 | K8: 2 | L8: 33.78907 | M8: =(100*L8)/(100+N8) -> 33.784002 | N8: 0.015 | O8: 0.0375
A9: Ký hiệu: | C9: МП-60 | F9: Số hiệu: | G9: 1046 | J9: 3 | K9: 3 | L9: 67.58286 | M9: =(100*L9)/(100+N9) -> 67.567995 | N9: 0.022 | O9: 0.0375
A10: Nước (hãng) sản xuất: | D10: Nga | J10: 4 | K10: 4 | L10: 67.57205 | M10: =(100*L10)/(100+N10) -> 67.567996 | N10: 0.006 | O10: 0.0375
A11: Đặc trưng kỹ thuật đo lường: | J11: 5 | K11: 5 | L11: 168.92576 | M11: =(100*L11)/(100+N11) -> 168.919 | N11: 0.004 | O11: 0.0375
B12: Phạm vi đo: (1 đến 60) kgf/cm2; | J12: 6 | K12: 6 | L12: 168.93927 | M12: =(100*L12)/(100+N12) -> 168.919 | N12: 0.012 | O12: 0.0375
B13: Cấp chính xác: 0,05 | J13: 7 | K13: 7 | L13: 337.90895 | M13: =(100*L13)/(100+N13) -> 337.838 | N13: 0.021 | O13: 0.0375
A14: Đơn vị sử dụng: Công ty CP Cơ khí Thủy lực Hải An | J14: 8 | K14: 8 | L14: 337.89543 | M14: =(100*L14)/(100+N14) -> 337.838 | N14: 0.017 | O14: 0.0375
A15: Phương pháp kiểm định: | F15: QTKĐ 1.159 : 2021 | J15: 9 | K15: 9 | L15: 675.77735 | M15: =(100*L15)/(100+N15) -> 675.676 | N15: 0.015 | O15: 0.0375
A16: Phương tiện kiểm định: | E16: Áp kế píttông PG7202 | J16: 10 | K16: 10 | L16: 675.75708 | M16: =(100*L16)/(100+N16) -> 675.676 | N16: 0.012 | O16: 0.0375
A17: Điều kiện kiểm định: | J17: 11 | K17: 11 | L17: 1689.4424 | M17: =(100*L17)/(100+N17) -> 1689.189 | N17: 0.015 | O17: 0.0375
B18: Nhiệt độ môi trường: | E18: (20 ± 2) ºC | J18: 12 | K18: 12 | L18: 1689.341 | M18: =(100*L18)/(100+N18) -> 1689.189 | N18: 0.009 | O18: 0.0375
B19: Độ ẩm môi trường | E19: (61 ± 5) %RH | J19: 13 | K19: 13 | L19: 3378.8848 | M19: =(100*L19)/(100+N19) -> 3378.378 | N19: 0.015 | O19: 0.0375
A20: Ngày kiểm định: | E20: 45881 | J20: 14 | K20: 14 | L20: 3378.8848 | M20: =(100*L20)/(100+N20) -> 3378.378 | N20: 0.015 | O20: 0.0375
J21: 15 | K21: 15 | L21: 6757.5002 | M21: =(100*L21)/(100+N21) -> 6756.757 | N21: 0.011 | O21: 0.0375
D22: KẾT QUẢ KIỂM ĐỊNH | J22: 16 | K22: 16 | L22: 6757.0273 | M22: =(100*L22)/(100+N22) -> 6756.757 | N22: 0.004 | O22: 0.0375
J23: 17 | K23: 17 | L23: 16893.074 | M23: =(100*L23)/(100+N23) -> 16891.892 | N23: 0.007 | O23: 0.0375
A24: 1. Kiểm tra bên ngoài: | J24: 18 | K24: 18 | L24: 16894.426 | M24: =(100*L24)/(100+N24) -> 16891.892 | N24: 0.015 | O24: 0.0375
B25:  Đạt
B26:  Không đạt
A27: 2. Kiểm tra kỹ thuật: (Xem các trang sau)
B28:  Đạt
B29:  Không đạt
A30: 3. Kiểm tra đo lường: (Xem các trang sau)
B31:  Đạt
B32:  Không đạt
B35: KIỂM ĐỊNH VIÊN | F35: NGƯỜI KIỂM SOÁT
B40: Lê Minh Châu | F40: Đỗ Hải Yến
I42: Trang 1/4 | O42: Trang 3/4
A43: KẾT QUẢ KIỂM ĐỊNH (tiếp theo)
A44: 2. Kiểm tra kỹ thuật:
A45: Bảng 2.1 - Phương của lực tác dụng và độ kín
A46: Thông số kiểm tra | F46: Giá trị xác định | H46: Giá trị cho phép
A47: Kiểm tra phương của lực tác dụng và độ vuông góc của đĩa cân gốc với trục của píttông
...

Sheet KQ KĐ (2)
A1: KẾT QUẢ KIỂM ĐỊNH (Kết thúc)
A2: 3.2 Xác định diện tích hiệu dụng
A3: Bảng 3 - Kết quả cân bằng áp suất
A4: TT | B4: Áp suất danh nghĩa, (kG/cm2) | C4: Áp kế pít tông cần kiểm định | G4: Áp suất khí quyển, hPa | H4: Độ ẩm môi trường, %RH | I4: Nhiệt độ môi trường, °C
C5: Số hiệu quả cân | D5: Khối lượng quả cân, g | E5: Số gam thêm vào | F5: Tổng khối lượng, g | N5: 9.9796291e-05
A6: 1 | B6: 6 | C6: 11,13,14,17 | D6: 5999.992 | E6: 0.008 | F6: =D6+E6 -> 6000 | G6: 1007.64 | H6: 60 | I6: 20.5 | M6: =B6*#REF! -> #NAME? | N6: =$N$5*D6/'Tính toán'!$D$3 -> 7427.8977
A7: 2 | B7: 12 | C7: 7,16 | D7: 11999.991 | E7: 0.009 | F7: =D7+E7 -> 12000 | G7: 1012.23 | H7: 64.1 | I7: 19.8 | M7: =B7*#REF! -> #NAME? | N7: =$N$5*D7/'Tính toán'!$D$3 -> 14855.804
A8: 3 | B8: 18 | C8: 9,10,18 | D8: 17999.96 | E8: 0.04 | F8: =D8+E8 -> 18000 | G8: 1011.7 | H8: 58.1 | I8: 20.3 | M8: =B8*#REF! -> #NAME? | N8: =$N$5*D8/'Tính toán'!$D$3 -> 22283.673
A9: 4 | B9: 24 | C9: 6,11,15 | D9: 23999.992 | E9: 0.008 | F9: =D9+E9 -> 24000 | G9: 1015.21 | H9: 62.2 | I9: 20.1 | M9: =B9*#REF! -> #NAME? | N9: =$N$5*D9/'Tính toán'!$D$3 -> 29711.621
A10: 5 | B10: 30 | C10: 5,17 | D10: 29999.962 | E10: 0.038 | F10: =D10+E10 -> 30000 | G10: 1009.12 | H10: 58.5 | I10: 19.7 | M10: =B10*#REF! -> #NAME? | N10: =$N$5*D10/'Tính toán'!$D$3 -> 37139.491
A11: 6 | B11: 36 | C11: 5,16,17 | D11: 35999.975 | E11: 0.025 | F11: =D11+E11 -> 36000 | G11: 1004.82 | H11: 63.4 | I11: 20.1 | M11: =B11*#REF! -> #NAME? | N11: =$N$5*D11/'Tính toán'!$D$4 -> 891278.64
A12: 7 | B12: 42 | C12: 1,2,13 | D12: 41999.995 | E12: 0.005 | F12: =D12+E12 -> 42000 | G12: 1009.7 | H12: 63.1 | I12: 20
A13: 8 | B13: 48 | C13: 1,9,11 | D13: 47999.994 | E13: 0.006 | F13: =D13+E13 -> 48000 | G13: 1011.61 | H13: 62.4 | I13: 20.2
A14: 9 | B14: 54 | C14: 5,11 | D14: 53999.994 | E14: 0.006 | F14: =D14+E14 -> 54000 | G14: 1007.15 | H14: 56.5 | I14: 19.6
A15: 10 | B15: 60 | C15: 9,13,14,17 | D15: 59999.976 | E15: 0.024 | F15: =D15+E15 -> 60000 | G15: 1013.06 | H15: 58.5 | I15: 20.5
A16: Diện tích hiệu dụng của pít tông: | D16: A0 = 0,99796 × 10-4 , m2
A17: 3.3 Xác định độ chính xác
A18: Độ không đảm bảo đo: | C18: uCmax = | D18: 18,900 × 10-3 (kG/cm2) | F18: tại p = 42,0 kG/cm2
C19: U(p) = | D19: 37,800 × 10-3 (kG/cm2) | F19: (với k = 2)
C20: Δ(p) = | D20: 0
A21: Độ chính xác: | C21: d = | D21: 0.00045
A23: 4. Kết luận: Đạt yêu cầu kỹ thuật đo lường
A24: Trang 4/4

Sheet Tính toán
A1: Phần tính toán (tạm thời bỏ qua ảnh hưởng các yếu tố phụ do điều kiện thiết bị phòng thí nghiệm không cho phép)
T2: bar | U2: kG/cm2
A3: Tiết diện píttông chuẩn A1 | D3: =8.06119*10^(-5) -> 8.06119e-05 | H3: A | I3: 9.9796291e-05 | J3: 9.9796291e-05 | K3: 9.9796291e-05 | L3: 9.9796291e-05 | M3: 9.9796291e-05 | R3: 1 | S3: 33.78501 | T3: =(S3*0.001*9.786673*0.00001)/9.97962912921334e-05 -> 0.033131777 | U3: =(S3*0.001*0.0001)/9.97962912921334e-05 -> 0.033853973
A4: Tiết diện píttông chuẩn A2 | D4: =4.03091*10^(-6) -> 4.03091e-06 | H4: m | I4: 10 | J4: 0.9 | K4: 1.2 | L4: 2 | M4: 0.4 | R4: 2 | S4: 33.78907 | T4: =(S4*0.001*9.786673*0.00001)/9.97962912921334e-05 -> 0.033135758 | U4: =(S4*0.001*0.0001)/9.97962912921334e-05 -> 0.033858042
H5: P, bar | I5: =(I4*9.786673*0.00001)/I3 -> 9.80665 | J5: =(J4*9.786673*0.00001)/J3 -> 0.8825985 | K5: =(K4*9.786673*0.00001)/K3 -> 1.176798 | L5: =(L4*9.786673*0.00001)/L3 -> 1.96133 | M5: =(M4*9.786673*0.00001)/M3 -> 0.392266 | N5: =SUM(I5:M5) -> 14.219643 | R5: 3 | S5: 67.58286 | T5: =(S5*0.001*9.786673*0.00001)/9.97962912921334e-05 -> 0.066276145 | U5: =(S5*0.001*0.0001)/9.97962912921334e-05 -> 0.067720813
R6: 4 | S6: 67.57205 | T6: =(S6*0.001*9.786673*0.00001)/9.97962912921334e-05 -> 0.066265544 | U6: =(S6*0.001*0.0001)/9.97962912921334e-05 -> 0.067709981
A7: g | B7: 9.786673 | H7: m, kg | I7: =S21 -> 387.03411 | R7: 5 | S7: 168.92576 | T7: =(S7*0.001*9.786673*0.00001)/9.97962912921334e-05 -> 0.16565958 | U7: =(S7*0.001*0.0001)/9.97962912921334e-05 -> 0.16927058
H8: P, Pa | I8: =(5*B7*100000)/10 -> 489333.65 | R8: 6 | S8: 168.93927 | T8: =(S8*0.001*9.786673*0.00001)/9.97962912921334e-05 -> 0.16567283 | U8: =(S8*0.001*0.0001)/9.97962912921334e-05 -> 0.16928412
H9: A, m2 | I9: =(0.99985*I7*B7)/I8 -> 0.0077395211 | R9: 7 | S9: 337.90895 | T9: =(S9*0.001*9.786673*0.00001)/9.97962912921334e-05 -> 0.33137548 | U9: =(S9*0.001*0.0001)/9.97962912921334e-05 -> 0.33859871
R10: 8 | S10: 337.89543 | T10: =(S10*0.001*9.786673*0.00001)/9.97962912921334e-05 -> 0.33136222 | U10: =(S10*0.001*0.0001)/9.97962912921334e-05 -> 0.33858516
R11: 9 | S11: 675.77735 | T11: =(S11*0.001*9.786673*0.00001)/9.97962912921334e-05 -> 0.66271119 | U11: =(S11*0.001*0.0001)/9.97962912921334e-05 -> 0.67715678
R12: 10 | S12: 675.75708 | T12: =(S12*0.001*9.786673*0.00001)/9.97962912921334e-05 -> 0.66269132 | U12: =(S12*0.001*0.0001)/9.97962912921334e-05 -> 0.67713647
R13: 11 | S13: 1689.4424 | T13: =(S13*0.001*9.786673*0.00001)/9.97962912921334e-05 -> 1.656777 | U13: =(S13*0.001*0.0001)/9.97962912921334e-05 -> 1.6928909
R14: 12 | S14: 1689.341 | T14: =(S14*0.001*9.786673*0.00001)/9.97962912921334e-05 -> 1.6566776 | U14: =(S14*0.001*0.0001)/9.97962912921334e-05 -> 1.6927894
R15: 13 | S15: 3378.8848 | T15: =(S15*0.001*9.786673*0.00001)/9.97962912921334e-05 -> 3.313554 | U15: =(S15*0.001*0.0001)/9.97962912921334e-05 -> 3.3857819
R16: 14 | S16: 3378.8848 | T16: =(S16*0.001*9.786673*0.00001)/9.97962912921334e-05 -> 3.313554 | U16: =(S16*0.001*0.0001)/9.97962912921334e-05 -> 3.3857819
R17: 15 | S17: 6757.5002 | T17: =(S17*0.001*9.786673*0.00001)/9.97962912921334e-05 -> 6.626844 | U17: =(S17*0.001*0.0001)/9.97962912921334e-05 -> 6.771294
R18: 16 | S18: 6757.0273 | T18: =(S18*0.001*9.786673*0.00001)/9.97962912921334e-05 -> 6.6263801 | U18: =(S18*0.001*0.0001)/9.97962912921334e-05 -> 6.77082
R19: 17 | S19: 16893.074 | T19: =(S19*0.001*9.786673*0.00001)/9.97962912921334e-05 -> 16.566447 | U19: =(S19*0.001*0.0001)/9.97962912921334e-05 -> 16.927557
R20: G | S20: 16894.426 | T20: =(S20*0.001*9.786673*0.00001)/9.97962912921334e-05 -> 16.567772 | U20: =(S20*0.001*0.0001)/9.97962912921334e-05 -> 16.928911
O21: =S3+S4+S5+S6+S7+S8 -> 540.59402 | S21: =AVERAGE(S3:S13) -> 387.03411 | T21: =SUM(T3:T20) -> 58.846288
